try {
    foo = 22;
} catch(e) {
    console.error("Caught exception: " + e);
}
