try {
    foo = 22;
} catch(e) {
    console.error("Caught exception: " + e);
}
// As of Dec 29 16:34 this program produces the correct output